<?xml version="1.0"?>
<robot name="ur7e_pyroki">

<!-- Base link of the robot -->
<link name="base_link"/>
<link name="base_link_inertia">
<inertial>
<mass value="4.0"/>
<origin rpy="0 0 0" xyz="0 0 0"/>
<inertia ixx="0.00443333156" ixy="0.0" ixz="0.0"
iyy="0.00443333156" iyz="0.0" izz="0.0072"/>
</inertial>
</link>

<link name="shoulder_link">
<inertial>
<mass value="3.761"/>
<origin rpy="0 0 0" xyz="0.0 -0.00193 -0.02561"/>
<inertia ixx="0.010267499999999999" ixy="0" ixz="0"
iyy="0.010267499999999999" iyz="0" izz="0.00666"/>
</inertial>
</link>

<link name="upper_arm_link">
<inertial>
<mass value="8.058"/>
<origin rpy="0 1.570796326794897 0" xyz="-0.2125 0.0 0.11336"/>
<inertia ixx="0.13388583541666665" ixy="0" ixz="0"
iyy="0.13388583541666665" iyz="0" izz="0.0151074"/>
</inertial>
</link>

<link name="forearm_link">
<inertial>
<mass value="2.846"/>
<origin rpy="0 1.570796326794897 0" xyz="-0.2422 0.0 0.0265"/>
<inertia ixx="0.03120936758333333" ixy="0" ixz="0"
iyy="0.03120936758333333" iyz="0" izz="0.004095"/>
</inertial>
</link>

<link name="wrist_1_link">
<inertial>
<mass value="1.37"/>
<origin rpy="0 0 0" xyz="0.0 -0.01634 -0.0018"/>
<inertia ixx="0.0025599" ixy="0" ixz="0"
iyy="0.0025599" iyz="0" izz="0.0021942"/>
</inertial>
</link>

<link name="wrist_2_link">
<inertial>
<mass value="1.3"/>
<origin rpy="0 0 0" xyz="0.0 0.01634 -0.0018"/>
<inertia ixx="0.0025599" ixy="0" ixz="0"
iyy="0.0025599" iyz="0" izz="0.0021942"/>
</inertial>
</link>

<link name="wrist_3_link">
<inertial>
<mass value="0.365"/>
<origin rpy="0 0 0" xyz="0.0 0.0 -0.001159"/>
<inertia ixx="9.890414008333333e-05" ixy="0" ixz="0"
iyy="9.890414008333333e-05" iyz="0" izz="0.0001321171875"/>
</inertial>
</link>

<!-- Flange and tool frame -->
<link name="flange"/>
<link name="tool0"/>

<!-- Joints: main 6-DoF chain + tool -->
<joint name="base_link-base_link_inertia" type="fixed">
<parent link="base_link"/>
<child link="base_link_inertia"/>
<origin rpy="0 0 3.141592653589793" xyz="0 0 0"/>
</joint>

<joint name="shoulder_pan_joint" type="revolute">
<parent link="base_link_inertia"/>
<child link="shoulder_link"/>
<origin rpy="0 0 0" xyz="0 0 0.1625"/>
<axis xyz="0 0 1"/>
<limit effort="150.0"
lower="-6.283185307179586"
upper="6.283185307179586"
velocity="3.141592653589793"/>
<dynamics damping="0" friction="0"/>
</joint>

<joint name="shoulder_lift_joint" type="revolute">
<parent link="shoulder_link"/>
<child link="upper_arm_link"/>
<origin rpy="1.570796327 0 0" xyz="0 0 0"/>
<axis xyz="0 0 1"/>
<limit effort="150.0"
lower="-6.283185307179586"
upper="6.283185307179586"
velocity="3.141592653589793"/>
<dynamics damping="0" friction="0"/>
</joint>

<joint name="elbow_joint" type="revolute">
<parent link="upper_arm_link"/>
<child link="forearm_link"/>
<origin rpy="0 0 0" xyz="-0.425 0 0"/>
<axis xyz="0 0 1"/>
<limit effort="150.0"
lower="-3.141592653589793"
upper="3.141592653589793"
velocity="3.141592653589793"/>
<dynamics damping="0" friction="0"/>
</joint>

<joint name="wrist_1_joint" type="revolute">
<parent link="forearm_link"/>
<child link="wrist_1_link"/>
<origin rpy="0 0 0" xyz="-0.3922 0 0.1333"/>
<axis xyz="0 0 1"/>
<limit effort="28.0"
lower="-6.283185307179586"
upper="6.283185307179586"
velocity="3.141592653589793"/>
<dynamics damping="0" friction="0"/>
</joint>

<joint name="wrist_2_joint" type="revolute">
<parent link="wrist_1_link"/>
<child link="wrist_2_link"/>
<origin rpy="1.570796327 0 0"
xyz="0 -0.0997 -2.044881182297852e-11"/>
<axis xyz="0 0 1"/>
<limit effort="28.0"
lower="-6.283185307179586"
upper="6.283185307179586"
velocity="3.141592653589793"/>
<dynamics damping="0" friction="0"/>
</joint>

<joint name="wrist_3_joint" type="revolute">
<parent link="wrist_2_link"/>
<child link="wrist_3_link"/>
<origin rpy="1.570796326589793 3.141592653589793 3.141592653589793"
xyz="0 0.0996 -2.042830148012698e-11"/>
<axis xyz="0 0 1"/>
<limit effort="28.0"
lower="-6.283185307179586"
upper="6.283185307179586"
velocity="3.141592653589793"/>
<dynamics damping="0" friction="0"/>
</joint>

<joint name="wrist_3-flange" type="fixed">
<parent link="wrist_3_link"/>
<child link="flange"/>
<origin rpy="0 -1.5707963267948966 -1.5707963267948966"
xyz="0 0 0"/>
</joint>

<joint name="flange-tool0" type="fixed">
<!-- default tool frame -->
<parent link="flange"/>
<child link="tool0"/>
<origin rpy="1.5707963267948966 0 1.5707963267948966"
xyz="0 0 0"/>
</joint>

</robot>
